<?xml version="1.0"?>
<robot xmlns:xacro="http://www.ros.org/wiki/xacro">

    <!-- TRANSMISSION -->
    <xacro:macro name="default_transmission" params="number">
        <transmission name="transmission_${number}" >
            <plugin>transmission_interface/SimpleTransmission</plugin>
            <actuator name="motor_${number}" roll="actuator1"/>
            <joint name="joint_${number}" roll="joint1">
                <mechanical_reduction>1.0</mechanical_reduction>

            </joint>
        </transmission>
    </xacro:macro>


    <!-- JOINTS  Virual or fixed-->

    <joint name="virtual" type="fixed">
        <parent link="world" />
        <child link="base_link" />
        <origin xyz="0.0 0.0 0.0" rpy="0.0 0.0 0.0" />
    </joint>

    <!-- JOINTS  Revolute-->

    <joint name="joint_1" type="revolute">
        <parent link="base_link" />
        <child link="base_plate" />
        <axis xyz="0 0 1" />
        <limit lower="${-pi/2}" upper="${pi/2}" velocity="10.0" effort="30.0" />
        <origin xyz="0 0 0.129" rpy="0 0 0" />
    </joint>

    <joint name="joint_2" type="revolute">
        <parent link="base_plate" />
        <child link="arm_1" />
        <axis xyz="0 1 0 " />
        <limit lower="${-pi/2}" upper="${pi/2}" velocity="10.0" effort="30.0" />
        <origin xyz="0.014 0.004 0.04" rpy="0 0 0" />
    </joint>

    <joint name="joint_3" type="revolute">
        <parent link="arm_1" />
        <child link="arm_2" />
        <axis xyz="0 1 0 " />
        <limit lower="-0.1" upper="2.77" velocity="10.0" effort="30.0" />
        <origin xyz="0 0 0.12" rpy="0 0 0" />
    </joint>

    <joint name="joint_4" type="revolute">
        <parent link="arm_2" />
        <child link="arm_3" />
        <axis xyz="0 0 1 " />
        <limit lower="${-pi/4}" upper="${pi/4}" velocity="10.0" effort="30.0" />
        <origin xyz="0.0045 0.007 0.09" rpy="0 0 0" />
    </joint>

    <joint name="joint_5" type="revolute">
        <parent link="arm_3" />
        <child link="claw_support" />
        <axis xyz="0 1 0 " />
        <limit lower="${-pi/4}" upper="${pi/4}" velocity="10.0" effort="30.0" />
        <origin xyz="-0.004 -0.015 0.03" rpy="0 0 0" />
    </joint>

    <joint name="joint_6" type="revolute">
        <parent link="claw_support" />
        <child link="gripper_right" />
        <axis xyz="1 0 0" />
        <limit lower="${-pi/6}" upper="0" velocity="10.0" effort="30.0" />
        <origin xyz="0.015 0.004 0.065" rpy="0 0 0" />
    </joint>

    <joint name="joint_7" type="revolute">
        <mimic joint="joint_6" multiplier="-1" offset="0" />
        <parent link="claw_support" />
        <child link="gripper_left" />
        <axis xyz="1 0 0" />
        <limit lower="0" upper="${pi/6}" velocity="10.0" effort="30.0" />
        <origin xyz="0.015 -0.03 0.065" rpy="0 0 0" />
    </joint>

    <xacro:default_transmission number="1"/>
    <xacro:default_transmission number="2"/>
    <xacro:default_transmission number="3"/>
    <xacro:default_transmission number="4"/>
    <xacro:default_transmission number="5"/>
    <xacro:default_transmission number="6"/>
    <xacro:default_transmission number="7"/>


</robot>