<?xml version="1.0"?>
<robot xmlns:xacro="http://www.ros.org/wiki/xacro" name="rca">


    <!-- LINKS -->
    <link name="world" />

    <link name="base_link">
        <xacro:default_inertial mass="3" />
        <visual>
            <origin xyz="0.0 0.0 -0.065" rpy="0.0 0.0 ${PI}" />
            <geometry>
                <mesh filename="package://rca_description/meshes/RCA_BASE_TOWER4URDF.stl"
                    scale="0.001 0.001 0.001" />
            </geometry>
            <material name="blue" />
        </visual>
        <collision>
            <origin xyz="0.0 0.0 -0.065" rpy="0.0 0.0 ${PI}" />
            <geometry>
                <mesh filename="package://rca_description/meshes/RCA_BASE_TOWER4URDF.stl"
                    scale="0.001 0.001 0.001" />
            </geometry>
        </collision>
    </link>

    <link name="base_plate">
        <xacro:default_inertial mass="0.5" />
        <visual>
            <origin xyz="0.0 0.0 0" rpy="${PI/2} 0.0 ${-PI/2}" />
            <geometry>
                <mesh filename="package://rca_description/meshes/Waist.stl"
                    scale="0.001 0.001 0.001" />
            </geometry>
            <material name="black" />
        </visual>
        <collision>
            <origin xyz="0.0 0.0 0" rpy="${PI/2} 0.0 ${-PI/2}" />
            <geometry>
                <mesh filename="package://rca_description/meshes/Waist.stl"
                    scale="0.001 0.001 0.001" />
            </geometry>
        </collision>
    </link>

    <link name="arm_1">
        <xacro:default_inertial mass="0.3" />
        <visual>
            <origin xyz="0.0 -0.001 0" rpy="${PI/2} 0 0" />
            <geometry>
                <mesh filename="package://rca_description/meshes/Arm_01.stl"
                    scale="0.001 0.001 0.001" />
            </geometry>
            <material name="red" />
        </visual>
        <collision>
            <origin xyz="0.0 -0.001 0" rpy="${PI/2} 0 0" />
            <geometry>
                <mesh filename="package://rca_description/meshes/Arm_01.stl"
                    scale="0.001 0.001 0.001" />
            </geometry>
        </collision>
    </link>

    <link name="arm_2">
        <xacro:default_inertial mass="0.3" />
        <visual>
            <origin xyz="0 0.0018 0.035" rpy="${PI/2} 0 ${PI}" />
            <geometry>
                <mesh filename="package://rca_description/meshes/Arm_02.stl"
                    scale="0.001 0.001 0.001" />
            </geometry>
            <material name="red" />
        </visual>
        <collision>
            <origin xyz="0 0.0018 0.035" rpy="${PI/2} 0 ${PI}" />
            <geometry>
                <mesh filename="package://rca_description/meshes/Arm_02.stl"
                scale="0.001 0.001 0.001" />
            </geometry>
        </collision>
    </link>

    <link name="arm_3">
        <xacro:default_inertial mass="0.2" />
        <visual>
            <origin xyz="-0.0035 0 0.0015" rpy="${PI/2} 0 ${PI}" />
            <geometry>
                <mesh filename="package://rca_description/meshes/Arm_03.stl"
                    scale="0.001 0.001 0.001" />
            </geometry>
            <material name="red" />
        </visual>
        <collision>
            <origin xyz="-0.0035 0 0.0015" rpy="${PI/2} 0 ${PI}" />
            <geometry>
                <mesh filename="package://rca_description/meshes/Arm_03.stl"
                    scale="0.001 0.001 0.001" />
            </geometry>
        </collision>
    </link>

    <link name="claw_support">
        <xacro:default_inertial mass="0.2" />
        <visual>
            <origin xyz="0.0095 0.005 0.063" rpy="0 0 ${-PI/2}" />
            <geometry>
                <mesh filename="package://rca_description/meshes/Gripper_base.stl"
                    scale="0.001 0.001 0.001" />
            </geometry>
            <material name="blue" />
        </visual>
        <collision>
            <origin xyz="0.0095 0.005 0.063" rpy="0 0 ${-PI/2}" />
            <geometry>
                <mesh filename="package://rca_description/meshes/Gripper_base.stl"
                scale="0.001 0.001 0.001" />
            </geometry>
        </collision>
    </link>

    <link name="gripper_right">
        <xacro:default_inertial mass="0.1" />
        <visual>
            <origin xyz="0 -0.003 -0.0065" rpy="${-PI/8} ${PI} 0" />
            <geometry>
                <mesh filename="package://rca_description/meshes/Gripper_1.stl"
                    scale="0.001 0.001 0.001" />
            </geometry>
            <material name="red" />
        </visual>
        <collision>
            <origin xyz="0 -0.003 -0.0065" rpy="${-PI/8} ${PI} 0" />
            <geometry>
                <mesh filename="package://rca_description/meshes/Gripper_1.stl"
                    scale="0.001 0.001 0.001" />
            </geometry>
        </collision>
    </link>

    <link name="gripper_left">
        <xacro:default_inertial mass="0.1" />
        <visual>
            <origin xyz="-0.008 0.003 -0.0063" rpy="${-PI/8} ${PI} ${PI}" />
            <geometry>
                <mesh filename="package://rca_description/meshes/Gripper_1_1.stl"
                    scale="0.001 0.001 0.001" />
            </geometry>
            <material name="red" />
        </visual>
        <collision>
            <origin xyz="-0.008 0.003 -0.0063" rpy="${-PI/8} ${PI} ${PI}" />
            <geometry>
                <mesh filename="package://rca_description/meshes/Gripper_1_1.stl"
                    scale="0.001 0.001 0.001" />
            </geometry>
        </collision>
    </link>

    <!-- JOINTS -->

    <!-- TRANSMISSION -->
    <xacro:macro name="default_transmission" params="number">
        <transmission name="transmission_${number}">
            <plugin>transmission_interface/SimpleTransmission</plugin>
            <actuator name="motor_${number}" role="actuator1"/>
            <joint name="joint_${number}"    role="joint1">
                <mechanical_reduction>1.0</mechanical_reduction>
            </joint>
        </transmission>
    </xacro:macro>


    <!-- JOINTS  Virual or fixed-->

    <joint name="virtual_joint" type="fixed">
        <parent link="world" />
        <child link="base_link" />
        <origin xyz="0.0 0.0 0.0" rpy="0.0 0.0 0.0" />
    </joint>

    <!-- JOINTS  Revolute-->

    <joint name="joint_1" type="revolute">
        <parent link="base_link" />
        <child link="base_plate" />
        <axis xyz="0 0 1" />
        <limit lower="-${PI/2}" upper="${PI/2}" velocity="${velocity}" effort="${effort}" />
        <origin xyz="0 0 0.129" rpy="0 0 0" />
    </joint>

    <joint name="joint_2" type="revolute">
        <parent link="base_plate" />
        <child link="arm_1" />
        <axis xyz="0 1 0 " />
        <limit lower="-${PI/2}" upper="${PI/2}"  velocity="${velocity}" effort="${effort}" />
        <origin xyz="0.014 0.004 0.04" rpy="0 0 0" />
    </joint>

    <joint name="joint_3" type="revolute">
        <parent link="arm_1" />
        <child link="arm_2" />
        <axis xyz="0 1 0 " />
        <limit lower="-${PI/2}" upper="${PI/2}"  velocity="${velocity}" effort="${effort}" />
        <origin xyz="0 0 0.12" rpy="0 ${PI/4} 0" />
    </joint>

    <joint name="joint_4" type="revolute">
        <parent link="arm_2" />
        <child link="arm_3" />
        <axis xyz="0 0 1 " />
        <limit lower="-${PI/4}" upper="${PI/4}"  velocity="${velocity}" effort="${effort}" />
        <origin xyz="0.0045 0.007 0.09" rpy="0 0 0" />
    </joint>

    <joint name="joint_5" type="revolute">
        <parent link="arm_3" />
        <child link="claw_support" />
        <axis xyz="0 1 0 " />
        <limit lower="-${PI/4}" upper="${PI/4}"  velocity="${velocity}" effort="${effort}" />
        <origin xyz="-0.004 -0.015 0.03" rpy="0 0 0" />
    </joint>

    <joint name="joint_6" type="revolute">
        <parent link="claw_support" />
        <child link="gripper_right" />
        <axis xyz="1 0 0" />
        <limit lower="-${PI/6}" upper="0.0"  velocity="${velocity}" effort="${effort}" />
        <origin xyz="0.015 0.004 0.065" rpy="0 0 0" />
    </joint>

    <joint name="joint_7" type="revolute">
        <mimic joint="joint_6" multiplier="-1" />
        <parent link="claw_support" />
        <child link="gripper_left" />
        <axis xyz="1 0 0" />
        <limit lower="0.0" upper="${PI/6}"  velocity="${velocity}" effort="${effort}" />
        <origin xyz="0.015 -0.03 0.065" rpy="0 0 0" />
    </joint>

    <xacro:default_transmission number="1"/>
    <xacro:default_transmission number="2"/>
    <xacro:default_transmission number="3"/>
    <xacro:default_transmission number="4"/>
    <xacro:default_transmission number="5"/>
    <xacro:default_transmission number="6"/>


</robot>